<mujoco>
  <compiler autolimits="true"/>

  <asset>
    <texture name="grid" type="2d" builtin="checker" width="512" height="512" rgb1=".1 .2 .3" rgb2=".2 .3 .4"/>
    <material name="grid" texture="grid" texrepeat="1 1" texuniform="true" reflectance=".2"/>
    <mesh name="chasis" scale="1 1 1"
      vertex="  .16 .12 -.05
                .16 .12 .05
                -.16 .12 -.05
                -.16 .12 .05
                .16 -.12 -.05
                .16 -.12 .05
                -.16 -.12 .05
                -.16 -.12 -.05"/>

    <texture type="skybox" builtin="gradient" rgb1="0.6 0.6 0.6" rgb2="0 0 0" width="512" height="512"/>
  </asset>

  <visual>
    <global offwidth="1536" offheight="864"/>
    <rgba haze=".3 .3 .3 1"/>
  </visual>

  <default>
    <joint damping=".03" actuatorfrcrange="-0.5 0.5"/>
    <default class="wheel">
      <geom type="capsule" size=".045 .01" rgba=".5 .5 1 1"/>
    </default>
    <default class="contact site">
      <site type="sphere" rgba="0.5 0 0 1" size="0.02 0.02 0.02"/>
    </default>
  </default>

  <worldbody>
    <light directional="true" diffuse=".8 .8 .8" specular=".2 .2 .2" pos="0 0 5" dir="0 0 -1"/>
    <geom name="floor" type="plane" size="0 0 .01" material="grid"/>
    <!-- <geom name="red_box" type="box" size=".2 .2 .5" rgba="1 0 0 1" pos="5 0 0.5"/> -->

    <body name="wall" pos="2.0 0 0">
        <geom name="wall left" type="box" size="0.05 2.0 1.0" pos="0 2.2 1.0" rgba="0 1 0 1"/>
        <geom name="wall right" type="box" size="0.05 2.0 1.0" pos="0 -2.2 1.0" rgba="0 1 0 1"/>
        <geom name="wall top" type="box" size="0.05 0.2 0.7" pos="0 0 1.3" rgba="0 1 0 1"/>
    </body>
    
    <body name="car" pos="0 0 .150">
      <joint armature="0" axis="1 0 0" damping="50" limited="false" name="rootx" pos="0 0 0" type="slide" actuatorfrclimited="false"/>
      <joint armature="0" axis="0 1 0" damping="50" limited="false" name="rooty" pos="0 0 0" stiffness="0" type="slide" actuatorfrclimited="false"/>
      <joint armature="0" axis="0 0 1" damping="5" limited="false" name="rootz" pos="0 0 0" stiffness="0" type="hinge" actuatorfrclimited="false"/>

      <site name="center_x" pos="0 0 0" type="sphere" size="0.001" axisangle="1 0 0 0"/>
      <site name="center_y" pos="0 0 0" type="sphere" size="0.001" axisangle="0 0 1 90"/>
      <geom name="chasis" type="mesh" mesh="chasis"/>

      <site name="contact site front left" type="box" pos=".2 .12 .05" size=".05 .05 .05"/>
      <site name="contact site front right" type="box" pos=".2 -.12 .05" size=".05 .05 .05"/>
      <site name="contact site front center" type="box" pos=".2 0 .05" size=".05 .05 .05"/>
      <!-- <site name="contact site front 1" type="box" pos=".2 0 .05" size=".1 .1 .1"/>
      <site name="contact site front 2" type="box" pos=".2 .02 .05" size=".1 .1 .1"/>
      <site name="contact site front 3" type="box" pos=".2 .04 .05" size=".1 .1 .1"/>
      <site name="contact site front 4" type="box" pos=".2 .06 .05" size=".1 .1 .1"/>
      <site name="contact site front 5" type="box" pos=".2 .08 .05" size=".1 .1 .1"/>
      <site name="contact site front 6" type="box" pos=".2 .1 .05" size=".1 .1 .1"/>
      <site name="contact site front 7" type="box" pos=".2 .12 .05" size=".1 .1 .1"/>

      <site name="contact site front -2" type="box" pos=".2 -.02 .05" size=".1 .1 .1"/>
      <site name="contact site front -3" type="box" pos=".2 -.04 .05" size=".1 .1 .1"/>
      <site name="contact site front -4" type="box" pos=".2 -.06 .05" size=".1 .1 .1"/>
      <site name="contact site front -5" type="box" pos=".2 -.08 .05" size=".1 .1 .1"/>
      <site name="contact site front -6" type="box" pos=".2 -.1 .05" size=".1 .1 .1"/>
      <site name="contact site front -7" type="box" pos=".2 -.12 .05" size=".1 .1 .1"/> -->

      <site name="imu site" pos="0 0 0"/>

      <body pos=".05 0 .059" quat="0 0 0 1">
        <geom name="upper arm" type="capsule" size="0.015" fromto="0 0 0  0 0 .131" rgba=".5 .1 .1 1"/>
        <joint name="shoulder"/>
        <geom name="shoulder" type="cylinder" pos="0 0 0" size=".025 .01" rgba=".5 .1 .8 .5" mass="0" group="1"/>

        <body pos="-0.01 0 .126" quat = "0 0 .707 .707">
          <geom name="forearm" type="capsule" size="0.01" fromto="0 0 -.025    0 0 .025" rgba=".5 .1 .1 1" mass="5"/>
          <joint name="elbow"/>
          <geom name="elbow" type="cylinder" pos="0 0 0" size=".02 .01" rgba=".5 .1 .8 .5" mass="0" group="1"/>

          <body pos="0.02 0 0" quat="0.707 0 -0.707 0" name="fixater">
            <geom name="camsphere" type="sphere" size="0.01" pos="0 0 0" rgba=".5 .1 .8 .5" mass="0"/>
            <site name="IMU" pos="0 0 0" type="sphere" size="0.001"/>
            <camera name="fixater" mode="fixed" fovy="45"/>
          </body>
        </body>
      </body>


      <body name="back left wheel" pos=".12 .09 -.07" zaxis="0 1 0">
        <joint name="bleft"/>
        <geom name="blw" class="wheel"/>
      </body>
      
      <body name="back right wheel" pos=".12 -.09 -.07" zaxis="0 1 0">
        <joint name="bright"/>
        <geom name="brw" class="wheel"/>
      </body>
      
      <body name="front left wheel" pos="-.12 .09 -.07" zaxis="0 1 0">
        <joint name="fleft"/>
        <geom name="flw" class="wheel"/>
      </body>
      <body name="front right wheel" pos="-.12 -.09 -.07" zaxis="0 1 0">
        <joint name="fright"/>
        <geom name="frw" class="wheel"/>
      </body>

      <body name="back left wheel-alt" pos=".12 .09 -.07" zaxis="1 0 0">
        <joint name="bleft-alt"/>
        <geom name="blw-a" class="wheel"/>
      </body>

      <body name="back right wheel-alt" pos=".12 -.09 -.07" zaxis="1 0 0">
        <joint name="bright-alt"/>
        <geom name="brw-a" class="wheel"/>
      </body>

      <body name="front right wheel-alt" pos="-.12 -.09 -.07" zaxis="1 0 0">
        <joint name="fright-alt"/>
        <geom name="frw-a" class="wheel"/>
      </body>

      <body name="front left wheel-alt" pos="-.12 .09 -.07" zaxis="1 0 0">
        <joint name="fleft-alt"/>
        <geom name="flw-a" class="wheel"/>
      </body>
    </body>
  </worldbody>

  <actuator>  
    <motor name="forward" site="center_x" ctrlrange="-100 100"/>
    <motor name="turn" joint="rootz" ctrlrange="-2 2"/>
    <motor name="horizontal" site="center_y" ctrlrange="-100 100"/>
    <velocity name="shoulderv" joint="shoulder" kv=".1" />
    <velocity name="elbowv" joint="elbow" kv=".1" />
  </actuator>
  <!-- <sensor>
    <accelerometer name="imu" site="imu site"/>
  </sensor> -->
  <sensor>
    <!-- <jointactuatorfrc name="right" joint="right"/>
    <jointactuatorfrc name="left" joint="left"/> -->
    <touch name="touch front left" site="contact site front left"/>
    <touch name="touch front right" site="contact site front right"/>
    <touch name="touch front center" site="contact site front center"/>

    <!-- <touch name="touch front 0" site="contact site front 1"/>

    <touch name="touch front 1" site="contact site front 2"/>
    <touch name="touch front 2" site="contact site front 3"/>
    <touch name="touch front 3" site="contact site front 4"/>
    <touch name="touch front 4" site="contact site front 5"/>
    <touch name="touch front 5" site="contact site front 6"/>
    <touch name="touch front 6" site="contact site front 7"/>

    <touch name="touch front -1" site="contact site front -2"/>
    <touch name="touch front -2" site="contact site front -3"/>
    <touch name="touch front -3" site="contact site front -4"/>
    <touch name="touch front -4" site="contact site front -5"/>
    <touch name="touch front -5" site="contact site front -6"/>
    <touch name="touch front -6" site="contact site front -7"/> -->

    <accelerometer name="imu" site="imu site" />
  </sensor>

</mujoco>

