<mujoco>
  <compiler autolimits="true"/>
  <option timestep="0.002"/>
  <asset>
    <texture name="grid" type="2d" builtin="checker" width="512" height="512" rgb1=".1 .2 .3" rgb2=".2 .3 .4"/>
    <material name="grid" texture="grid" texrepeat="1 1" texuniform="true" reflectance=".2"/>
    <mesh name="chasis" scale="1 1 1"
      vertex="  .16 .12 -.05
                .16 .12 .05
                -.16 .12 -.05
                -.16 .12 .05
                .16 -.12 -.05
                .16 -.12 .05
                -.16 -.12 .05
                -.16 -.12 -.05"/>

    <texture type="skybox" builtin="gradient" rgb1="0.6 0.6 0.6" rgb2="0 0 0" width="512" height="512"/>
  </asset>

  <visual>
    <global offwidth="1536" offheight="864"/>
    <rgba haze=".3 .3 .3 1"/>
  </visual>

  <default>
    <joint damping=".03" actuatorfrcrange="-0.5 0.5"/>
    <default class="wheel">
      <geom type="capsule" size=".045 .01" rgba=".5 .5 1 1"/>
    </default>
    <default class="contact site">
      <site type="sphere" rgba="0.5 0 0 1" size="0.02 0.02 0.02"/>
    </default>
  </default>

  <worldbody>
    <light directional="true" diffuse=".8 .8 .8" specular=".2 .2 .2" pos="0 0 5" dir="0 0 -1"/>
    <geom name="floor" type="plane" size="0 0 .01" material="grid"/>

    <body name="wall" pos="2.0 -0.5 0">
        <geom name="wall left" type="box" size="0.05 1.0 1.0" pos="0 1.2 1.0" rgba="0 1 0 1"/>
        <geom name="wall right" type="box" size="0.05 1.0 1.0" pos="0 -1.2 1.0" rgba="0 1 0 1"/>
        <geom name="wall top" type="box" size="0.05 0.2 0.7" pos="0 0 1.3" rgba="0 1 0 1"/>
    </body>
    

    <body name="car" pos="0 0 .03">
      <freejoint/>
      <geom name="chasis" type="mesh" mesh="chasis"/>

      <site name="contact site front left" class="contact site" pos=".16 .12 .05"/>
      <site name="contact site front right" class="contact site" pos=".16 -.12 .05"/>
      <site name="imu site" pos="0 0 0"/>

      <body pos=".05 0 .059" quat="0 0 0 1">
        <geom name="upper arm" type="capsule" size="0.015" fromto="0 0 0  0 0 .131" rgba=".5 .1 .1 1"/>
        <joint name="shoulder"/>
        <geom name="shoulder" type="cylinder" pos="0 0 0" size=".025 .01" rgba=".5 .1 .8 .5" mass="0" group="1"/>

        <body pos="-0.01 0 .126" quat = "0 0 .707 .707">
          <geom name="forearm" type="capsule" size="0.01" fromto="0 0 -.025    0 0 .025" rgba=".5 .1 .1 1" mass="5"/>
          <joint name="elbow"/>
          <geom name="elbow" type="cylinder" pos="0 0 0" size=".02 .01" rgba=".5 .1 .8 .5" mass="0" group="1"/>

          <body pos="0.02 0 0" quat="0.707 0 -0.707 0" name="fixater">
            <geom type="sphere" size="0.01" pos="0 0 0" rgba=".5 .1 .8 .5" mass="0"/>
            <camera name="fixater" mode="fixed" fovy="45"/>
          </body>
        </body>
      </body>


      <body name="back left wheel" pos=".12 .09 -.07" zaxis="0 1 0">
        <joint name="bleft"/>
        <geom name="blw" class="wheel"/>
      </body>
      
      <body name="back right wheel" pos=".12 -.09 -.07" zaxis="0 1 0">
        <joint name="bright"/>
        <geom name="brw" class="wheel"/>
      </body>
      
      <body name="front left wheel" pos="-.12 .09 -.07" zaxis="0 1 0">
        <joint name="fleft"/>
        <geom name="flw" class="wheel"/>
      </body>
      <body name="front right wheel" pos="-.12 -.09 -.07" zaxis="0 1 0">
        <joint name="fright"/>
        <geom name="frw" class="wheel"/>
      </body>

      <body name="back left wheel-alt" pos=".12 .09 -.07" zaxis="1 0 0">
        <joint name="bleft-alt"/>
        <geom name="blw-a" class="wheel"/>
      </body>

      <body name="back right wheel-alt" pos=".12 -.09 -.07" zaxis="1 0 0">
        <joint name="bright-alt"/>
        <geom name="brw-a" class="wheel"/>
      </body>

      <body name="front right wheel-alt" pos="-.12 -.09 -.07" zaxis="1 0 0">
        <joint name="fright-alt"/>
        <geom name="frw-a" class="wheel"/>
      </body>

      <body name="front left wheel-alt" pos="-.12 .09 -.07" zaxis="1 0 0">
        <joint name="fleft-alt"/>
        <geom name="flw-a" class="wheel"/>
      </body>
    </body>
  </worldbody>

  <tendon>
    <fixed name="forward">
      <joint joint="bleft" coef=".5"/>
      <joint joint="fleft" coef=".5"/>
      <joint joint="bright" coef=".5"/>
      <joint joint="fright" coef=".5"/>
    </fixed>
    <fixed name="turn">
      <joint joint="bleft-alt" coef="-.5"/>
      <joint joint="bright-alt" coef="-.5"/>
      <joint joint="fleft-alt" coef=".5"/>
      <joint joint="fright-alt" coef=".5"/>
    </fixed>
    <fixed name="horizontal">
      <joint joint="bleft-alt" coef=".5"/>
      <joint joint="bright-alt" coef=".5"/>
      <joint joint="fleft-alt" coef=".5"/>
      <joint joint="fright-alt" coef=".5"/>
    </fixed>
  </tendon>

  <actuator>  
    <motor name="forward" tendon="forward" ctrlrange="-2 2"/>
    <motor name="turn" tendon="turn" ctrlrange="-2 2"/>
    <motor name="horizontal" tendon="horizontal" ctrlrange="-2 2"/>
    <velocity name="shoulderv" joint="shoulder" kv=".1" />
    <velocity name="elbowv" joint="elbow" kv=".1" /> 
  </actuator>

  <contact>
    <pair name="blc" geom2="floor" geom1="blw" condim="3" friction="0.01 1"/>
    <pair name="brc" geom2="floor" geom1="brw" condim="3" friction="0.01 1"/>
    <pair name="frc" geom2="floor" geom1="frw" condim="3" friction="0.01 1"/>
    <pair name="flc" geom2="floor" geom1="flw" condim="3" friction="0.01 1"/>


    <pair name="blca" geom2="floor" geom1="blw-a" condim="3" friction="0.01 1"/>
    <pair name="brca" geom2="floor" geom1="brw-a" condim="3" friction="0.01 1"/>
    <pair name="frca" geom2="floor" geom1="frw-a" condim="3" friction="0.01 1"/>
    <pair name="flca" geom2="floor" geom1="flw-a" condim="3" friction="0.01 1"/>

    <exclude name="blp" body1="back left wheel" body2="back left wheel-alt"/>
    <exclude name="brp" body1="back right wheel" body2="back right wheel-alt"/>
    <exclude name="flp" body1="front left wheel" body2="front left wheel-alt"/>
    <exclude name="frp" body1="front right wheel" body2="front right wheel-alt"/>
  </contact>

  <sensor>
    <!-- <jointactuatorfrc name="right" joint="right"/>
    <jointactuatorfrc name="left" joint="left"/> -->
    <touch name="touch front left" site="contact site front left"/>
    <touch name="touch front right" site="contact site front right"/>
    <accelerometer name="imu" site="imu site" />
  </sensor>
</mujoco>
